Workbook

Sheet README
A1: Home Energy Audit [2] - Dorm Room Energy & Carbon Audit Workbook
A2: Jayash Sahu | SEE8115 | Hall 13, CityU Lee Shau Kee Student Residence Village, Room 1003B, 10/F | Ma On Shan, New Territories, Hong Kong
A4: Purpose | B4: Systematic energy assessment of the auditor's home (a shared student-hostel room) following the EMSD Code of Practice for Building Energy Audit (EAC 2018) and the EPD/EMSD GHG Guidelines for Buildings in Hong Kong: baseline consumption, consumption patterns, carbon inventory and Energy Management Opportunities.
A5: Boundary | B5: Household = Room 1003B (15 m², 2 occupants) + allocated shares of the shared washroom (4 users) and floor kitchen (32 residents) + the household's own hall-laundry use. Hall common services (lifts, corridors, central plant) are outside the boundary.
A6: Period | B6: Data collected 1 Jan - 11 Oct 2026; results expressed as a typical 12-month baseline year.
A8: Colour legend | B8: Blue text = input | C8: Yellow fill = assumption | D8: Black = formula | E8: Green = link to another sheet
A10: Key results (all live formulas)
A11: Indicator | B11: Value | C11: Unit | D11: Where calculated
A12: Room AC energy (baseline, Octopus spend) | B12: =AC_KWH -> 810.81081 | C12: kWh/yr | D12: AC_Baseline
A13: Room AC energy, bottom-up energy-label check | B13: =AC_BU -> 884.48667 | C13: kWh/yr | D13: AC_Baseline
A14: Household electricity (room + allocated shared services) | B14: =HH_KWH -> 2586.3877 | C14: kWh/yr | D14: Inventory
A15: of which inside the 15 m² room | B15: =ROOM_KWH -> 1219.6108 | C15: kWh/yr | D15: Inventory
A16: Electricity per person | B16: =HH_KWH/OCC -> 1293.1938 | C16: kWh/person/yr | D16: Inventory
A17: Room EUI | B17: =ROOM_EUI_MJ -> 292.70659 | C17: MJ/m²/yr | D17: Monthly / Breakdown
A18: Scope 1 (refrigerant screening) | B18: =S1_KG -> 16.4375 | C18: kg CO2e/yr | D18: GHG_Inventory
A19: Scope 2 - CLP-specific factor 0.34 | B19: =S2_CLP -> 879.37181 | C19: kg CO2e/yr | D19: GHG_Inventory
A20: Scope 2 - territory default 0.7 | B20: =S2_DEF -> 1810.4714 | C20: kg CO2e/yr | D20: GHG_Inventory
A21: Scope 3 (water, sewage, paper) | B21: =S3_KG -> 43.310128 | C21: kg CO2e/yr | D21: GHG_Inventory
A22: Household total (CLP basis) | B22: =TOT_CLP -> 939.11943 | C22: kg CO2e/yr | D22: GHG_Inventory
A23: Household total (default basis) | B23: =TOT_DEF -> 1870.219 | C23: kg CO2e/yr | D23: GHG_Inventory
A24: Per person (CLP basis) | B24: =TOT_CLP/OCC -> 469.55972 | C24: kg CO2e/person/yr | D24: GHG_Inventory
A25: Daily-activity extension (auditor) | B25: =LIFE_KG -> 4601.4683 | C25: kg CO2e/yr | D25: Lifestyle_Scope3
A26: Auditor's personal total | B26: =PERSONAL_KG -> 5071.028 | C26: kg CO2e/yr | D26: Lifestyle_Scope3
A27: Category I EMO saving (household) | B27: =EMO_CAT1_KWH -> 503.21791 | C27: kWh/yr | D27: EMO_Register
A28: Category I EMO saving as % of household electricity | B28: =EMO_CAT1_KWH/HH_KWH -> 0.19456399 | C28: % | D28: EMO_Register
A30: Sheet guide
A31: Inputs | B31: All inputs with unit, data quality and source; HKO 1991-2020 monthly temperatures
A32: AC_Baseline | B32: Room AC: top-down (Octopus spend) vs bottom-up (HK energy label) reconciliation
A33: HotWater | B33: Monthly shower hot-water energy from first principles
A34: Inventory | B34: Equipment inventory with allocation of shared services (EAC Step 1-2)
A35: Monthly | B35: Monthly profile, monthly EUI and emissions
A36: Breakdown | B36: End-use and EAC-category breakdown, KPIs and HK benchmarks
A37: GHG_Inventory | B37: Scope 1-2-3 inventory in HK GHG Guidelines table format
A38: Lifestyle_Scope3 | B38: Auditor's commuting, flights and diet (reported separately)
A39: EMO_Register | B39: 18 EMOs by EAC category, with savings, costs, payback and CO2e
A40: Sensitivity | B40: One-at-a-time sensitivity of the key assumptions
A41: EE-EAes_Summary | B41: Executive summary in the structure of EMSD form EE-EAes
A42: EE-EAes_Entry_Guide | B42: Cell-by-cell values to type into the official macro-enabled EE-EAes form
... A44: Sources | B44: Full references with URLs

Sheet Inputs
A1: Inputs & assumptions
A2: Blue = input value; yellow fill = assumed typical value (flagged in the report); every formula in the workbook points here.
A4: Name | B4: Parameter | C4: Value | D4: Unit | E4: Data quality | F4: Source | G4: Notes | I4: Month | J4: Days | K4: Hot season (1 = May-Oct) | L4: HKO mean air temp (°C)
A5: Boundary & occupancy | I5: Jan | J5: 31 | K5: 0 | L5: 16.5
A6: OCC | B6: Occupants of Room 1003B (household) | C6: 2 | D6: persons | E6: Reported | F6: S29 | G6: Auditor + 1 roommate | I6: Feb | J6: 28 | K6: 0 | L6: 17.1
A7: WR_USERS | B7: Users of the shared washroom | C7: 4 | D7: persons | E7: Reported | F7: S29 | G7: Shared by 4 residents | I7: Mar | J7: 31 | K7: 0 | L7: 19.4
A8: KIT_USERS | B8: Residents sharing the floor kitchen (allocation basis) | C8: 32 | D8: persons | E8: Reported | F8: S29 | G8: ~20 use it actively; allocation is per resident with access | I8: Apr | J8: 30 | K8: 0 | L8: 23
A9: OCC_WKDAY_H | B9: Hours in room per weekday (22:00-11:00) | C9: 13 | D9: h/day | E9: Reported | F9: S29 | G9: Q13 | I9: May | J9: 31 | K9: 1 | L9: 26.3
A10: OCC_SAT_H | B10: Hours in room on Saturday | C10: 20 | D10: h/day | E10: Reported | F10: S29 | G10: Q14 | I10: Jun | J10: 30 | K10: 1 | L10: 28.3
A11: OCC_SUN_H | B11: Hours in room on Sunday | C11: 18 | D11: h/day | E11: Reported | F11: S29 | G11: Q14 | I11: Jul | J11: 31 | K11: 1 | L11: 28.9
A12: ROOM_AREA | B12: Internal floor area of Room 1003B | C12: 15 | D12: m2 | E12: Reported | F12: S29 | G12: Approximate, from hall information | I12: Aug | J12: 31 | K12: 1 | L12: 28.7
A13: DAYS_HOT | B13: Days in hot season (May-Oct) | C13: 184 | D13: days | E13: Derived | G13: 31+30+31+31+30+31 | I13: Sep | J13: 30 | K13: 1 | L13: 27.9
A14: DAYS_COOL | B14: Days in cool season (Nov-Apr) | C14: 181 | D14: days | E14: Derived | G14: 30+31+31+28+31+30 | I14: Oct | J14: 31 | K14: 1 | L14: 25.7
A15: MJ_PER_KWH | B15: Energy conversion | C15: 3.6 | D15: MJ/kWh | E15: Published | F15: S3 | G15: Per EE-EAes Part 2 | I15: Nov | J15: 30 | K15: 0 | L15: 22.2
A16: CP_WATER | B16: Specific heat of water | C16: 4.186 | D16: kJ/kg.K | E16: Published | G16: Physical constant (1 L = 1 kg) | I16: Dec | J16: 31 | K16: 0 | L16: 18.2
A17: Tariff & emission factors | I17: Year | J17: =SUM(J5:J16) -> 365 | K17: =SUM(K5:K16) -> 6 | L17: =SUMPRODUCT(J5:J16,L5:L16)/J17 -> 23.549315
A18: TARIFF | B18: Electricity price used to convert AC spend to kWh (proxy) | C18: 1.406 | D18: HK$/kWh | E18: Published | F18: S6 | G18: CLP 2026 average net tariff; CityU's own Octopus AC rate not published - see Sensitivity | I18: S8: HKO 1991-2020 normals (HKO HQ), day-weighted from 10-day & half-monthly normals; annual mean 23.5 °C.
A19: TARIFF_LOW | B19: Comparator hostel AC rate - low | C19: 1.2 | D19: HK$/kWh | E19: Published | F19: S25 | G19: CUHK hostels
A20: TARIFF_HIGH | B20: Comparator hostel AC rate - high | C20: 2.31 | D20: HK$/kWh | E20: Published | F20: S25 | G20: HKU JCSV IV
A21: EF_CLP | B21: CLP Power HK emission factor (2025, latest) | C21: 0.34 | D21: kg CO2e/kWh | E21: Published | F21: S5 | G21: Power-company-specific factor (Guideline Table 5)
A22: EF_CLP_PREV | B22: CLP Power HK emission factor (2024) | C22: 0.38 | D22: kg CO2e/kWh | E22: Published | F22: S5 | G22: For sensitivity
A23: EF_DEFAULT | B23: Territory-wide default electricity factor | C23: 0.7 | D23: kg CO2e/kWh | E23: Published | F23: S2 | G23: Guideline Table 5 - must also be reported
A24: WSD_FRESH | B24: WSD unit electricity - fresh water | C24: 0.624 | D24: kWh/m3 | E24: Published | F24: S11 | G24: x 0.7 kg/kWh per Guideline Table 8
A25: WSD_SALT | B25: WSD unit electricity - salt (flushing) water | C25: 0.362 | D25: kWh/m3 | E25: Published | F25: S11 | G25: x 0.7 kg/kWh (optional item)
A26: DSD_KWH | B26: DSD unit electricity - sewage treated | C26: 0.29 | D26: kWh/m3 | E26: Published | F26: S12 | G26: x 0.7 kg/kWh per Guideline Table 9
A27: SEWER_FRAC | B27: Fraction of fresh water entering sewer (residential) | C27: 1 | D27: - | E27: Published | F27: S2 | G27: Guideline Table 9 note
A28: PAPER_EF | B28: Paper to landfill emission factor | C28: 4.8 | D28: kg CO2e/kg | E28: Published | F28: S2 | G28: Guideline Table 7
A29: GWP_R32 | B29: GWP of HFC-32 (R32) | C29: 650 | D29: - | E29: Published | F29: S2 | G29: Guideline Table 3-1
A30: GWP_R410A | B30: GWP of R-410A | C30: 1725 | D30: - | E30: Published | F30: S2 | G30: Guideline Table 3-1
A31: LEAK | B31: Annual refrigerant leak rate (screening) | C31: 0.04 | D31: fraction/yr | E31: Published | F31: S21 | G31: IPCC 2006 range 1-10%; 4% typical for developed economies
A32: Room air-conditioner
A33: AC_SPEND_HOT | B33: Octopus AC spend - hot month (May-Oct), both occupants | C33: 140 | D33: HK$/month | E33: Reported | F33: S29 | G33: Q18
A34: AC_SPEND_COOL | B34: Octopus AC spend - cool month (Nov-Apr), both occupants | C34: 50 | D34: HK$/month | E34: Reported | F34: S29 | G34: Q18
A35: AC_SPEND_STATED | B35: Stated overall average AC spend | C35: 120 | D35: HK$/month | E35: Reported | F35: S29 | G35: Initial answer - used as upper-bound scenario
A36: AC_RATED_KW | B36: Rated input power (cooling) | C36: 1.192 | D36: kW | E36: Nameplate / label | F36: S28 | G36: Midea MW-12CRF8E
A37: AC_CAP_KW | B37: Rated cooling capacity | C37: 3.34 | D37: kW | E37: Nameplate / label | F37: S28 | G37: 11,400 Btu/h
A38: AC_CSPF | B38: Cooling seasonal performance factor | C38: 4.6618 | D38: - | E38: Nameplate / label | F38: S28 | G38: HK Energy Label Grade 1
A39: AC_LABEL_KWH | B39: Label annual energy consumption (cooling) | C39: 362 | D39: kWh/yr | E39: Nameplate / label | F39: S28 | G39: Basis 1,200 h/yr
A40: LABEL_HOURS | B40: Operating hours behind HK label figure | C40: 1200 | D40: h/yr | E40: Published | F40: S9 | G40: EMSD label basis
A41: AC_H_HOT | B41: AC operating hours - typical hot-season day | C41: 12 | D41: h/day | E41: Reported | F41: S29 | G41: Q20 (on all night)
...

Sheet AC_Baseline
A1: Room air-conditioner baseline (Midea MW-12CRF8E, Octopus pre-paid)
A2: Top-down = reported Octopus spend ÷ electricity price. Bottom-up = HK Energy Label average input power (362 kWh per 1,200 h) × reported operating hours.
A5: Month | B5: Days | C5: Season | D5: Octopus AC spend (HK$) | E5: Top-down kWh (spend ÷ tariff) | F5: AC operating hours (reported) | G5: Bottom-up kWh (label kW × hours) | H5: Scenario: stated HK$120/month (kWh) | J5: Reconciliation & diagnostics | K5: Value | L5: Unit | M5: Comment
A6: Jan | B6: =Inputs!J5 -> 31 | C6: =IF(Inputs!K5=1,"Hot","Cool") -> Cool | D6: =IF(Inputs!K5=1,AC_SPEND_HOT,AC_SPEND_COOL) -> 50 | E6: =D6/TARIFF -> 35.561878 | F6: =B6*IF(Inputs!K5=1,AC_H_HOT,AC_H_COOL) -> 124 | G6: =F6*AC_LABEL_KWH/LABEL_HOURS -> 37.406667 | H6: =AC_SPEND_STATED/TARIFF -> 85.348506 | J6: Label average input power (HK label basis) | K6: =AC_LABEL_KWH/LABEL_HOURS -> 0.30166667 | L6: kW | M6: 362 kWh / 1,200 h
A7: Feb | B7: =Inputs!J6 -> 28 | C7: =IF(Inputs!K6=1,"Hot","Cool") -> Cool | D7: =IF(Inputs!K6=1,AC_SPEND_HOT,AC_SPEND_COOL) -> 50 | E7: =D7/TARIFF -> 35.561878 | F7: =B7*IF(Inputs!K6=1,AC_H_HOT,AC_H_COOL) -> 112 | G7: =F7*AC_LABEL_KWH/LABEL_HOURS -> 33.786667 | H7: =AC_SPEND_STATED/TARIFF -> 85.348506 | J7: Rated input power (nameplate) | K7: =AC_RATED_KW -> 1.192 | L7: kW | M7: Full-load inverter input
A8: Mar | B8: =Inputs!J7 -> 31 | C8: =IF(Inputs!K7=1,"Hot","Cool") -> Cool | D8: =IF(Inputs!K7=1,AC_SPEND_HOT,AC_SPEND_COOL) -> 50 | E8: =D8/TARIFF -> 35.561878 | F8: =B8*IF(Inputs!K7=1,AC_H_HOT,AC_H_COOL) -> 124 | G8: =F8*AC_LABEL_KWH/LABEL_HOURS -> 37.406667 | H8: =AC_SPEND_STATED/TARIFF -> 85.348506 | J8: Annual operating hours (reported pattern) | K8: =F18 -> 2932 | L8: h/yr | M8: 12 h/day hot, 4 h/day cool
A9: Apr | B9: =Inputs!J8 -> 30 | C9: =IF(Inputs!K8=1,"Hot","Cool") -> Cool | D9: =IF(Inputs!K8=1,AC_SPEND_HOT,AC_SPEND_COOL) -> 50 | E9: =D9/TARIFF -> 35.561878 | F9: =B9*IF(Inputs!K8=1,AC_H_HOT,AC_H_COOL) -> 120 | G9: =F9*AC_LABEL_KWH/LABEL_HOURS -> 36.2 | H9: =AC_SPEND_STATED/TARIFF -> 85.348506 | J9: BASELINE: top-down annual AC energy | K9: =E18 -> 810.81081 | L9: kWh/yr | M9: Used in the inventory
A10: May | B10: =Inputs!J9 -> 31 | C10: =IF(Inputs!K9=1,"Hot","Cool") -> Hot | D10: =IF(Inputs!K9=1,AC_SPEND_HOT,AC_SPEND_COOL) -> 140 | E10: =D10/TARIFF -> 99.573257 | F10: =B10*IF(Inputs!K9=1,AC_H_HOT,AC_H_COOL) -> 372 | G10: =F10*AC_LABEL_KWH/LABEL_HOURS -> 112.22 | H10: =AC_SPEND_STATED/TARIFF -> 85.348506 | J10: Bottom-up annual AC energy (label method) | K10: =G18 -> 884.48667 | L10: kWh/yr | M10: Independent physical check
A11: Jun | B11: =Inputs!J10 -> 30 | C11: =IF(Inputs!K10=1,"Hot","Cool") -> Hot | D11: =IF(Inputs!K10=1,AC_SPEND_HOT,AC_SPEND_COOL) -> 140 | E11: =D11/TARIFF -> 99.573257 | F11: =B11*IF(Inputs!K10=1,AC_H_HOT,AC_H_COOL) -> 360 | G11: =F11*AC_LABEL_KWH/LABEL_HOURS -> 108.6 | H11: =AC_SPEND_STATED/TARIFF -> 85.348506 | J11: Difference, bottom-up vs top-down | K11: =K10/K9-1 -> 0.090866889 | L11: % | M11: Within ±10% = good agreement
A12: Jul | B12: =Inputs!J11 -> 31 | C12: =IF(Inputs!K11=1,"Hot","Cool") -> Hot | D12: =IF(Inputs!K11=1,AC_SPEND_HOT,AC_SPEND_COOL) -> 140 | E12: =D12/TARIFF -> 99.573257 | F12: =B12*IF(Inputs!K11=1,AC_H_HOT,AC_H_COOL) -> 372 | G12: =F12*AC_LABEL_KWH/LABEL_HOURS -> 112.22 | H12: =AC_SPEND_STATED/TARIFF -> 85.348506 | J12: Upper-bound scenario (stated HK$120 × 12) | K12: =H18 -> 1024.1821 | L12: kWh/yr | M12: Not reconciled with seasonal answers
A13: Aug | B13: =Inputs!J12 -> 31 | C13: =IF(Inputs!K12=1,"Hot","Cool") -> Hot | D13: =IF(Inputs!K12=1,AC_SPEND_HOT,AC_SPEND_COOL) -> 140 | E13: =D13/TARIFF -> 99.573257 | F13: =B13*IF(Inputs!K12=1,AC_H_HOT,AC_H_COOL) -> 372 | G13: =F13*AC_LABEL_KWH/LABEL_HOURS -> 112.22 | H13: =AC_SPEND_STATED/TARIFF -> 85.348506 | J13: Implied Octopus rate if bottom-up is right | K13: =D18/G18 -> 1.2888832 | L13: HK$/kWh | M13: Cf. CUHK 1.20 - HKU 2.31 (S25)
A14: Sep | B14: =Inputs!J13 -> 30 | C14: =IF(Inputs!K13=1,"Hot","Cool") -> Hot | D14: =IF(Inputs!K13=1,AC_SPEND_HOT,AC_SPEND_COOL) -> 140 | E14: =D14/TARIFF -> 99.573257 | F14: =B14*IF(Inputs!K13=1,AC_H_HOT,AC_H_COOL) -> 360 | G14: =F14*AC_LABEL_KWH/LABEL_HOURS -> 108.6 | H14: =AC_SPEND_STATED/TARIFF -> 85.348506 | J14: Average input power while running (top-down) | K14: =E18/F18 -> 0.27653848 | L14: kW | M14: Inverter part-load operation
A15: Oct | B15: =Inputs!J14 -> 31 | C15: =IF(Inputs!K14=1,"Hot","Cool") -> Hot | D15: =IF(Inputs!K14=1,AC_SPEND_HOT,AC_SPEND_COOL) -> 140 | E15: =D15/TARIFF -> 99.573257 | F15: =B15*IF(Inputs!K14=1,AC_H_HOT,AC_H_COOL) -> 372 | G15: =F15*AC_LABEL_KWH/LABEL_HOURS -> 112.22 | H15: =AC_SPEND_STATED/TARIFF -> 85.348506 | J15: Equivalent full-load hours at rated input | K15: =E18/AC_RATED_KW -> 680.21041 | L15: h/yr
A16: Nov | B16: =Inputs!J15 -> 30 | C16: =IF(Inputs!K15=1,"Hot","Cool") -> Cool | D16: =IF(Inputs!K15=1,AC_SPEND_HOT,AC_SPEND_COOL) -> 50 | E16: =D16/TARIFF -> 35.561878 | F16: =B16*IF(Inputs!K15=1,AC_H_HOT,AC_H_COOL) -> 120 | G16: =F16*AC_LABEL_KWH/LABEL_HOURS -> 36.2 | H16: =AC_SPEND_STATED/TARIFF -> 85.348506 | J16: Hot-season (May-Oct) AC energy | K16: =SUMIF(C6:C17,"Hot",E6:E17) -> 597.43954 | L16: kWh/yr
A17: Dec | B17: =Inputs!J16 -> 31 | C17: =IF(Inputs!K16=1,"Hot","Cool") -> Cool | D17: =IF(Inputs!K16=1,AC_SPEND_HOT,AC_SPEND_COOL) -> 50 | E17: =D17/TARIFF -> 35.561878 | F17: =B17*IF(Inputs!K16=1,AC_H_HOT,AC_H_COOL) -> 124 | G17: =F17*AC_LABEL_KWH/LABEL_HOURS -> 37.406667 | H17: =AC_SPEND_STATED/TARIFF -> 85.348506 | J17: Hot-season share of AC energy | K17: =K16/K9 -> 0.73684211 | L17: %
A18: Year | B18: =SUM(B6:B17) -> 365 | D18: =SUM(D6:D17) -> 1140 | E18: =SUM(E6:E17) -> 810.81081 | F18: =SUM(F6:F17) -> 2932 | G18: =SUM(G6:G17) -> 884.48667 | H18: =SUM(H6:H17) -> 1024.1821 | J18: Cool-season (Nov-Apr) AC energy | K18: =K9-K16 -> 213.37127 | L18: kWh/yr
J19: Annual AC spend (both occupants) | K19: =D18 -> 1140 | L19: HK$/yr | M19: HK$570 per person
J20: Approx. cooling delivered (top-down × label CSPF) | K20: =K9*AC_CSPF -> 3779.8378 | L20: kWh(th)/yr | M20: Seasonal efficiency basis

Sheet HotWater
A1: Shower hot water - Stiebel Eltron DHB-E 27 instantaneous heater (shared washroom)
A2: Energy = litres × 4.186 kJ/kg.K × (40 °C - cold-water inlet) ÷ 3,600 ÷ efficiency. Inlet temperature taken as the HKO monthly mean air temperature (assumption).
A5: Month | B5: Days | C5: Cold-water inlet ≈ HKO mean (°C) | D5: Temperature rise to 40 °C (K) | E5: Shower water per person (L/day) | F5: Heater energy per person (kWh/day) | G5: Household heater energy (kWh/month) | H5: Heater power needed at full flow (kW) | J5: Diagnostics | K5: Value | L5: Unit
A6: Jan | B6: =Inputs!J5 -> 31 | C6: =Inputs!L5 -> 16.5 | D6: =SHOWER_T-C6 -> 23.5 | E6: =SHOWERS*SHOWER_MIN*SHOWER_FLOW -> 45 | F6: =E6*CP_WATER*D6/3600/HEATER_EFF -> 1.2420581 | G6: =F6*B6*OCC -> 77.007601 | H6: =SHOWER_FLOW/60*CP_WATER*D6/HEATER_EFF -> 14.904697 | J6: Heater rating at 380 V (DHB-E 27) | K6: =HEATER_KW -> 24.4 | L6: kW
A7: Feb | B7: =Inputs!J6 -> 28 | C7: =Inputs!L6 -> 17.1 | D7: =SHOWER_T-C7 -> 22.9 | E7: =SHOWERS*SHOWER_MIN*SHOWER_FLOW -> 45 | F7: =E7*CP_WATER*D7/3600/HEATER_EFF -> 1.210346 | G7: =F7*B7*OCC -> 67.779374 | H7: =SHOWER_FLOW/60*CP_WATER*D7/HEATER_EFF -> 14.524152 | J7: Peak power needed for one shower (January) | K7: =H18 -> 14.904697 | L7: kW
A8: Mar | B8: =Inputs!J7 -> 31 | C8: =Inputs!L7 -> 19.4 | D8: =SHOWER_T-C8 -> 20.6 | E8: =SHOWERS*SHOWER_MIN*SHOWER_FLOW -> 45 | F8: =E8*CP_WATER*D8/3600/HEATER_EFF -> 1.0887828 | G8: =F8*B8*OCC -> 67.504535 | H8: =SHOWER_FLOW/60*CP_WATER*D8/HEATER_EFF -> 13.065394 | J8: Capacity headroom (rating ÷ need) | K8: =K6/K7 -> 1.6370678 | L8: ×
A9: Apr | B9: =Inputs!J8 -> 30 | C9: =Inputs!L8 -> 23 | D9: =SHOWER_T-C9 -> 17 | E9: =SHOWERS*SHOWER_MIN*SHOWER_FLOW -> 45 | F9: =E9*CP_WATER*D9/3600/HEATER_EFF -> 0.8985101 | G9: =F9*B9*OCC -> 53.910606 | H9: =SHOWER_FLOW/60*CP_WATER*D9/HEATER_EFF -> 10.782121 | J9: Household shower energy | K9: =G18 -> 634.71811 | L9: kWh/yr
A10: May | B10: =Inputs!J9 -> 31 | C10: =Inputs!L9 -> 26.3 | D10: =SHOWER_T-C10 -> 13.7 | E10: =SHOWERS*SHOWER_MIN*SHOWER_FLOW -> 45 | F10: =E10*CP_WATER*D10/3600/HEATER_EFF -> 0.72409343 | G10: =F10*B10*OCC -> 44.893793 | H10: =SHOWER_FLOW/60*CP_WATER*D10/HEATER_EFF -> 8.6891212 | J10: Per person | K10: =G18/OCC -> 317.35905 | L10: kWh/yr
A11: Jun | B11: =Inputs!J10 -> 30 | C11: =Inputs!L10 -> 28.3 | D11: =SHOWER_T-C11 -> 11.7 | E11: =SHOWERS*SHOWER_MIN*SHOWER_FLOW -> 45 | F11: =E11*CP_WATER*D11/3600/HEATER_EFF -> 0.61838636 | G11: =F11*B11*OCC -> 37.103182 | H11: =SHOWER_FLOW/60*CP_WATER*D11/HEATER_EFF -> 7.4206364 | J11: Shower water per person | K11: =E6*365/1000 -> 16.425 | L11: m3/yr
A12: Jul | B12: =Inputs!J11 -> 31 | C12: =Inputs!L11 -> 28.9 | D12: =SHOWER_T-C12 -> 11.1 | E12: =SHOWERS*SHOWER_MIN*SHOWER_FLOW -> 45 | F12: =E12*CP_WATER*D12/3600/HEATER_EFF -> 0.58667424 | G12: =F12*B12*OCC -> 36.373803 | H12: =SHOWER_FLOW/60*CP_WATER*D12/HEATER_EFF -> 7.0400909 | J12: January vs July daily energy | K12: =F6/F12 -> 2.1171171 | L12: ×
A13: Aug | B13: =Inputs!J12 -> 31 | C13: =Inputs!L12 -> 28.7 | D13: =SHOWER_T-C13 -> 11.3 | E13: =SHOWERS*SHOWER_MIN*SHOWER_FLOW -> 45 | F13: =E13*CP_WATER*D13/3600/HEATER_EFF -> 0.59724495 | G13: =F13*B13*OCC -> 37.029187 | H13: =SHOWER_FLOW/60*CP_WATER*D13/HEATER_EFF -> 7.1669394
A14: Sep | B14: =Inputs!J13 -> 30 | C14: =Inputs!L13 -> 27.9 | D14: =SHOWER_T-C14 -> 12.1 | E14: =SHOWERS*SHOWER_MIN*SHOWER_FLOW -> 45 | F14: =E14*CP_WATER*D14/3600/HEATER_EFF -> 0.63952778 | G14: =F14*B14*OCC -> 38.371667 | H14: =SHOWER_FLOW/60*CP_WATER*D14/HEATER_EFF -> 7.6743333
A15: Oct | B15: =Inputs!J14 -> 31 | C15: =Inputs!L14 -> 25.7 | D15: =SHOWER_T-C15 -> 14.3 | E15: =SHOWERS*SHOWER_MIN*SHOWER_FLOW -> 45 | F15: =E15*CP_WATER*D15/3600/HEATER_EFF -> 0.75580556 | G15: =F15*B15*OCC -> 46.859944 | H15: =SHOWER_FLOW/60*CP_WATER*D15/HEATER_EFF -> 9.0696667
A16: Nov | B16: =Inputs!J15 -> 30 | C16: =Inputs!L15 -> 22.2 | D16: =SHOWER_T-C16 -> 17.8 | E16: =SHOWERS*SHOWER_MIN*SHOWER_FLOW -> 45 | F16: =E16*CP_WATER*D16/3600/HEATER_EFF -> 0.94079293 | G16: =F16*B16*OCC -> 56.447576 | H16: =SHOWER_FLOW/60*CP_WATER*D16/HEATER_EFF -> 11.289515
A17: Dec | B17: =Inputs!J16 -> 31 | C17: =Inputs!L16 -> 18.2 | D17: =SHOWER_T-C17 -> 21.8 | E17: =SHOWERS*SHOWER_MIN*SHOWER_FLOW -> 45 | F17: =E17*CP_WATER*D17/3600/HEATER_EFF -> 1.1522071 | G17: =F17*B17*OCC -> 71.436838 | H17: =SHOWER_FLOW/60*CP_WATER*D17/HEATER_EFF -> 13.826485
A18: Year | B18: =SUM(B6:B17) -> 365 | C18: =SUMPRODUCT(B6:B17,C6:C17)/B18 -> 23.549315 | D18: =SUMPRODUCT(B6:B17,D6:D17)/B18 -> 16.450685 | E18: =E6 -> 45 | F18: =G18/B18/OCC -> 0.86947686 | G18: =SUM(G6:G17) -> 634.71811 | H18: =MAX(H6:H17) -> 14.904697

Sheet Inventory
A1: Equipment inventory and annual energy (EAC 2018 Step 1-2)
A2: Household = Room 1003B (2 occupants). Room loads count in full; shared washroom fixed loads at 2/4; shared kitchen fixed loads at 2/32; usage-based items (showers, cooking, laundry) at the household's own use.
A6: ID | B6: Space | C6: Item | D6: Make / model / evidence | E6: Power basis (W) | F6: Qty | G6: Use (h/day) or basis | H6: Item annual kWh | I6: Household share | J6: Household kWh/yr | K6: Per person kWh/yr | L6: End-use | M6: EAC 8.1(g)(iv) category | N6: Data quality | O6: Photo / note
A7: R1 | B7: Room | C7: Window air-conditioner | D7: Midea MW-12CRF8E, 1.5 HP inverter, R32, Grade 1 | E7: =AC_RATED_KW*1000 -> 1192 | F7: 1 | G7: Octopus spend ÷ tariff | H7: =AC_KWH -> 810.81081 | I7: 1 | J7: =H7*I7 -> 810.81081 | K7: =J7/OCC -> 405.40541 | L7: Air-conditioning | M7: Air-conditioning | N7: Reported spend + label | O7: 03a, 03b
A8: R2 | B8: Room | C8: Ceiling LED linear battens | D8: 2 surface battens (no label visible) | E8: =CEIL_W -> 20 | F8: =CEIL_N -> 2 | G8: =CEIL_H -> 6 | H8: =E8*F8*G8*365/1000 -> 87.6 | I8: 1 | J8: =H8*I8 -> 87.6 | K8: =J8/OCC -> 43.8 | L8: Lighting | M8: Lighting | N8: Assumed W, reported h | O8: 05a
A9: R3 | B9: Room | C9: Under-shelf LED desk lights | D9: Integrated in furniture | E9: =DESK_W -> 10 | F9: =DESK_N -> 2 | G9: =DESK_H -> 4 | H9: =E9*F9*G9*365/1000 -> 29.2 | I9: 1 | J9: =H9*I9 -> 29.2 | K9: =J9/OCC -> 14.6 | L9: Lighting | M9: Lighting | N9: Assumed | O9: 05b
A10: R4 | B10: Room | C10: Oscillating desk fan | D10: ZW02-180, 20 W nameplate | E10: =FAN_W -> 20 | F10: 1 | G10: =FAN_H -> 12 | H10: =E10*F10*G10*365/1000 -> 87.6 | I10: 1 | J10: =H10*I10 -> 87.6 | K10: =J10/OCC -> 43.8 | L10: Air movement (fan) | M10: Air-conditioning | N10: Nameplate + reported | O10: 06b
A11: R5 | B11: Room | C11: Laptops (auditor + roommate) | D11: HP 65 W adapter TPN-CA17 (avg draw 50%) | E11: =LAPTOP_W*LAPTOP_LF -> 32.5 | F11: =LAPTOP_N -> 2 | G11: =LAPTOP_H -> 8 | H11: =E11*F11*G11*365/1000 -> 189.8 | I11: 1 | J11: =H11*I11 -> 189.8 | K11: =J11/OCC -> 94.9 | L11: Plug loads | M11: Others | N11: Nameplate + assumed LF | O11: 06a
A12: R6 | B12: Room | C12: Phone chargers | D12: Typical 20 W fast charger | E12: =PHONE_W -> 20 | F12: =PHONE_N -> 2 | G12: =PHONE_H -> 1 | H12: =E12*F12*G12*365/1000 -> 14.6 | I12: 1 | J12: =H12*I12 -> 14.6 | K12: =J12/OCC -> 7.3 | L12: Plug loads | M12: Others | N12: Assumed W, reported h | O12: -
A13: W1 | B13: Washroom | C13: Instantaneous water heater (household showers) | D13: Stiebel Eltron DHB-E 27, 24.4 kW @380 V | E13: =HEATER_KW*1000 -> 24400 | F13: 1 | G13: See HotWater sheet | H13: =HW_KWH -> 634.71811 | I13: 1 | J13: =H13*I13 -> 634.71811 | K13: =J13/OCC -> 317.35905 | L13: Hot water | M13: Others | N13: Physics model | O13: 08a, 08e
A14: W2 | B14: Washroom | C14: Window exhaust fan (runs 24 h) | D14: J.E.E. window fan (label not visible) | E14: =WR_FAN_W -> 30 | F14: 1 | G14: =WR_FAN_H -> 24 | H14: =E14*F14*G14*365/1000 -> 262.8 | I14: =OCC/WR_USERS -> 0.5 | J14: =H14*I14 -> 131.4 | K14: =J14/OCC -> 65.7 | L14: Ventilation | M14: Air-conditioning | N14: Assumed W, reported h | O14: 08c, 08d
A15: W3 | B15: Washroom | C15: LED downlights (occupancy sensor) | D15: 3 surface downlights | E15: =WR_LIGHT_W -> 10 | F15: =WR_LIGHT_N -> 3 | G15: =WR_LIGHT_H -> 3 | H15: =E15*F15*G15*365/1000 -> 32.85 | I15: =OCC/WR_USERS -> 0.5 | J15: =H15*I15 -> 16.425 | K15: =J15/OCC -> 8.2125 | L15: Lighting | M15: Lighting | N15: Assumed W, reported h | O15: 08b
A16: K1 | B16: Kitchen | C16: Refrigerators | D16: Panasonic NR-BV361B, Grade 1, 263 kWh/yr label | F16: =FRIDGE_N -> 2 | G16: Energy label | H16: =FRIDGE_N*FRIDGE_KWH -> 526 | I16: =OCC/KIT_USERS -> 0.0625 | J16: =H16*I16 -> 32.875 | K16: =J16/OCC -> 16.4375 | L16: Refrigeration | M16: Others | N16: Energy label | O16: 09i
A17: K2 | B17: Kitchen | C17: 3-temperature water dispenser | D17: Aquatek AQ-1323T, 750 W heater + 160 W compressor | E17: 910 | F17: 1 | G17: 1.5 kWh/day (assumed) | H17: =DISP_KWH_DAY*365 -> 547.5 | I17: =OCC/KIT_USERS -> 0.0625 | J17: =H17*I17 -> 34.21875 | K17: =J17/OCC -> 17.109375 | L17: Drinking water | M17: Others | N17: Assumed | O17: 09a, 09b
A18: K3 | B18: Kitchen | C18: Split air-conditioner | D18: Toshiba RAS-24J2KCV-HK, 7.0 kW, R410A, Grade 1 (688 kWh/1,200 h) | E18: =KAC_LABEL_KWH/LABEL_HOURS*1000 -> 573.33333 | F18: 1 | G18: 8 h/day hot, 4 h/day cool | H18: =KAC_LABEL_KWH/LABEL_HOURS*(KAC_H_HOT*DAYS_HOT+KAC_H_COOL*DAYS_COOL) -> 1259.04 | I18: =OCC/KIT_USERS -> 0.0625 | J18: =H18*I18 -> 78.69 | K18: =J18/OCC -> 39.345 | L18: Air-conditioning | M18: Air-conditioning | N18: Label + observed | O18: 09f, 09g
A19: K4 | B19: Kitchen | C19: Kitchen lighting | D19: Not photographed | E19: =KLIGHT_W -> 15 | F19: =KLIGHT_N -> 6 | G19: =KLIGHT_H -> 16 | H19: =E19*F19*G19*365/1000 -> 525.6 | I19: =OCC/KIT_USERS -> 0.0625 | J19: =H19*I19 -> 32.85 | K19: =J19/OCC -> 16.425 | L19: Lighting | M19: Lighting | N19: Assumed | O19: -
A20: K5 | B20: Kitchen | C20: Induction cooking (household) | D20: Philips HD4911/80, 2,100 W max, Grade 2 (88.1%) | E20: =COOK_KW*1000 -> 1000 | F20: =OCC -> 2 | G20: =COOK_SESS*COOK_H/7 -> 0.42857143 | H20: =COOK_SESS*52*COOK_H*COOK_KW*OCC -> 312 | I20: 1 | J20: =H20*I20 -> 312 | K20: =J20/OCC -> 156 | L20: Cooking | M20: Others | N20: Reported use + assumed kW | O20: 09c-09e
A21: L1 | B21: Laundry | C21: Washing machine (household) | D21: Hall machine, cold wash 45 min | F21: =OCC -> 2 | G21: 1 load/week each | H21: =LAUNDRY_WK*52*WASH_KWH*OCC -> 31.2 | I21: 1 | J21: =H21*I21 -> 31.2 | K21: =J21/OCC -> 15.6 | L21: Laundry | M21: Others | N21: Reported use + assumed kWh | O21: -
A22: L2 | B22: Laundry | C22: Tumble dryer (household) | D22: Hall machine, 12 min per load | E22: =DRY_KW*1000 -> 3000 | F22: =OCC -> 2 | G22: 12 min/load | H22: =LAUNDRY_WK*52*DRY_KW*DRY_MIN/60*OCC -> 62.4 | I22: 1 | J22: =H22*I22 -> 62.4 | K22: =J22/OCC -> 31.2 | L22: Laundry | M22: Others | N22: Reported use + assumed kW | O22: -
A23: Total | J23: =SUM(J7:J22) -> 2586.3877 | K23: =SUM(K7:K22) -> 1293.1938
C26: Space | D26: Household kWh/yr | E26: % of household | F26: Per person kWh/yr
C27: Room 1003B (15 m²) | D27: =SUMIF($B$7:$B$22,"Room",$J$7:$J$22) -> 1219.6108 | E27: =D27/$D$31 -> 0.47154989 | F27: =D27/OCC -> 609.80541
C28: Shared washroom | D28: =SUMIF($B$7:$B$22,"Washroom",$J$7:$J$22) -> 782.54311 | E28: =D28/$D$31 -> 0.30256219 | F28: =D28/OCC -> 391.27155
C29: Shared kitchen | D29: =SUMIF($B$7:$B$22,"Kitchen",$J$7:$J$22) -> 490.63375 | E29: =D29/$D$31 -> 0.18969846 | F29: =D29/OCC -> 245.31688
C30: Hall laundry | D30: =SUMIF($B$7:$B$22,"Laundry",$J$7:$J$22) -> 93.6 | E30: =D30/$D$31 -> 0.03618947 | F30: =D30/OCC -> 46.8
C31: Total household | D31: =SUM(D27:D30) -> 2586.3877 | E31: =SUM(E27:E30) -> 1 | F31: =D31/OCC -> 1293.1938
C32: Outside the room (shared / usage-based) | D32: =D31-D27 -> 1366.7769 | E32: =D32/D31 -> 0.52845011
C33: Check: space total - inventory total (must be 0) | D33: =ROUND(D31-J23,6) -> 0

Sheet Monthly
A1: Monthly energy, EUI and emissions profile (typical baseline year)
A2: Feeds EAC 2018 §8.1(g)(iii) monthly EUI and EE-EAes Part 2 item 5. Room-only = loads inside the 15 m² room.
A5: Month | B5: Days | C5: Season | D5: Room AC | E5: Desk fan | F5: Room lighting | G5: Room plug loads | H5: Hot water | I5: Washroom fan + lights (share) | J5: Kitchen AC (share) | K5: Kitchen fridges, dispenser, lights (share) | L5: Cooking | M5: Laundry | N5: Household total kWh | O5: Household total MJ | P5: Room-only kWh | Q5: Room EUI (MJ/m²) | R5: Per person kWh | S5: kg CO2e (CLP 0.34) | T5: kg CO2e (default 0.7)
A6: Jan | B6: =Inputs!J5 -> 31 | C6: =IF(Inputs!K5=1,"Hot","Cool") -> Cool | D6: =AC_Baseline!E6 -> 35.561878 | E6: =Inventory!$J$10*B6/365 -> 7.44 | F6: =(Inventory!$J$8+Inventory!$J$9)*B6/365 -> 9.92 | G6: =(Inventory!$J$11+Inventory!$J$12)*B6/365 -> 17.36 | H6: =HotWater!G6 -> 77.007601 | I6: =(Inventory!$J$14+Inventory!$J$15)*B6/365 -> 12.555 | J6: =KAC_LABEL_KWH/LABEL_HOURS*B6*IF(Inputs!K5=1,KAC_H_HOT,KAC_H_COOL)*Inventory!$I$18 -> 4.4433333 | K6: =(Inventory!$J$16+Inventory!$J$17+Inventory!$J$19)*B6/365 -> 8.4883733 | L6: =Inventory!$J$20*B6/365 -> 26.49863 | M6: =(Inventory!$J$21+Inventory!$J$22)*B6/365 -> 7.949589 | N6: =SUM(D6:M6) -> 207.2244 | O6: =N6*MJ_PER_KWH -> 746.00786 | P6: =SUM(D6:G6) -> 70.281878 | Q6: =P6*MJ_PER_KWH/ROOM_AREA -> 16.867651 | R6: =N6/OCC -> 103.6122 | S6: =N6*EF_CLP -> 70.456298 | T6: =N6*EF_DEFAULT -> 145.05708
A7: Feb | B7: =Inputs!J6 -> 28 | C7: =IF(Inputs!K6=1,"Hot","Cool") -> Cool | D7: =AC_Baseline!E7 -> 35.561878 | E7: =Inventory!$J$10*B7/365 -> 6.72 | F7: =(Inventory!$J$8+Inventory!$J$9)*B7/365 -> 8.96 | G7: =(Inventory!$J$11+Inventory!$J$12)*B7/365 -> 15.68 | H7: =HotWater!G7 -> 67.779374 | I7: =(Inventory!$J$14+Inventory!$J$15)*B7/365 -> 11.34 | J7: =KAC_LABEL_KWH/LABEL_HOURS*B7*IF(Inputs!K6=1,KAC_H_HOT,KAC_H_COOL)*Inventory!$I$18 -> 4.0133333 | K7: =(Inventory!$J$16+Inventory!$J$17+Inventory!$J$19)*B7/365 -> 7.6669178 | L7: =Inventory!$J$20*B7/365 -> 23.934247 | M7: =(Inventory!$J$21+Inventory!$J$22)*B7/365 -> 7.180274 | N7: =SUM(D7:M7) -> 188.83602 | O7: =N7*MJ_PER_KWH -> 679.80968 | P7: =SUM(D7:G7) -> 66.921878 | Q7: =P7*MJ_PER_KWH/ROOM_AREA -> 16.061251 | R7: =N7/OCC -> 94.418012 | S7: =N7*EF_CLP -> 64.204248 | T7: =N7*EF_DEFAULT -> 132.18522
A8: Mar | B8: =Inputs!J7 -> 31 | C8: =IF(Inputs!K7=1,"Hot","Cool") -> Cool | D8: =AC_Baseline!E8 -> 35.561878 | E8: =Inventory!$J$10*B8/365 -> 7.44 | F8: =(Inventory!$J$8+Inventory!$J$9)*B8/365 -> 9.92 | G8: =(Inventory!$J$11+Inventory!$J$12)*B8/365 -> 17.36 | H8: =HotWater!G8 -> 67.504535 | I8: =(Inventory!$J$14+Inventory!$J$15)*B8/365 -> 12.555 | J8: =KAC_LABEL_KWH/LABEL_HOURS*B8*IF(Inputs!K7=1,KAC_H_HOT,KAC_H_COOL)*Inventory!$I$18 -> 4.4433333 | K8: =(Inventory!$J$16+Inventory!$J$17+Inventory!$J$19)*B8/365 -> 8.4883733 | L8: =Inventory!$J$20*B8/365 -> 26.49863 | M8: =(Inventory!$J$21+Inventory!$J$22)*B8/365 -> 7.949589 | N8: =SUM(D8:M8) -> 197.72134 | O8: =N8*MJ_PER_KWH -> 711.79682 | P8: =SUM(D8:G8) -> 70.281878 | Q8: =P8*MJ_PER_KWH/ROOM_AREA -> 16.867651 | R8: =N8/OCC -> 98.860669 | S8: =N8*EF_CLP -> 67.225255 | T8: =N8*EF_DEFAULT -> 138.40494
A9: Apr | B9: =Inputs!J8 -> 30 | C9: =IF(Inputs!K8=1,"Hot","Cool") -> Cool | D9: =AC_Baseline!E9 -> 35.561878 | E9: =Inventory!$J$10*B9/365 -> 7.2 | F9: =(Inventory!$J$8+Inventory!$J$9)*B9/365 -> 9.6 | G9: =(Inventory!$J$11+Inventory!$J$12)*B9/365 -> 16.8 | H9: =HotWater!G9 -> 53.910606 | I9: =(Inventory!$J$14+Inventory!$J$15)*B9/365 -> 12.15 | J9: =KAC_LABEL_KWH/LABEL_HOURS*B9*IF(Inputs!K8=1,KAC_H_HOT,KAC_H_COOL)*Inventory!$I$18 -> 4.3 | K9: =(Inventory!$J$16+Inventory!$J$17+Inventory!$J$19)*B9/365 -> 8.2145548 | L9: =Inventory!$J$20*B9/365 -> 25.643836 | M9: =(Inventory!$J$21+Inventory!$J$22)*B9/365 -> 7.6931507 | N9: =SUM(D9:M9) -> 181.07402 | O9: =N9*MJ_PER_KWH -> 651.86649 | P9: =SUM(D9:G9) -> 69.161878 | Q9: =P9*MJ_PER_KWH/ROOM_AREA -> 16.598851 | R9: =N9/OCC -> 90.537012 | S9: =N9*EF_CLP -> 61.565168 | T9: =N9*EF_DEFAULT -> 126.75182
A10: May | B10: =Inputs!J9 -> 31 | C10: =IF(Inputs!K9=1,"Hot","Cool") -> Hot | D10: =AC_Baseline!E10 -> 99.573257 | E10: =Inventory!$J$10*B10/365 -> 7.44 | F10: =(Inventory!$J$8+Inventory!$J$9)*B10/365 -> 9.92 | G10: =(Inventory!$J$11+Inventory!$J$12)*B10/365 -> 17.36 | H10: =HotWater!G10 -> 44.893793 | I10: =(Inventory!$J$14+Inventory!$J$15)*B10/365 -> 12.555 | J10: =KAC_LABEL_KWH/LABEL_HOURS*B10*IF(Inputs!K9=1,KAC_H_HOT,KAC_H_COOL)*Inventory!$I$18 -> 8.8866667 | K10: =(Inventory!$J$16+Inventory!$J$17+Inventory!$J$19)*B10/365 -> 8.4883733 | L10: =Inventory!$J$20*B10/365 -> 26.49863 | M10: =(Inventory!$J$21+Inventory!$J$22)*B10/365 -> 7.949589 | N10: =SUM(D10:M10) -> 243.56531 | O10: =N10*MJ_PER_KWH -> 876.83511 | P10: =SUM(D10:G10) -> 134.29326 | Q10: =P10*MJ_PER_KWH/ROOM_AREA -> 32.230382 | R10: =N10/OCC -> 121.78265 | S10: =N10*EF_CLP -> 82.812205 | T10: =N10*EF_DEFAULT -> 170.49572
A11: Jun | B11: =Inputs!J10 -> 30 | C11: =IF(Inputs!K10=1,"Hot","Cool") -> Hot | D11: =AC_Baseline!E11 -> 99.573257 | E11: =Inventory!$J$10*B11/365 -> 7.2 | F11: =(Inventory!$J$8+Inventory!$J$9)*B11/365 -> 9.6 | G11: =(Inventory!$J$11+Inventory!$J$12)*B11/365 -> 16.8 | H11: =HotWater!G11 -> 37.103182 | I11: =(Inventory!$J$14+Inventory!$J$15)*B11/365 -> 12.15 | J11: =KAC_LABEL_KWH/LABEL_HOURS*B11*IF(Inputs!K10=1,KAC_H_HOT,KAC_H_COOL)*Inventory!$I$18 -> 8.6 | K11: =(Inventory!$J$16+Inventory!$J$17+Inventory!$J$19)*B11/365 -> 8.2145548 | L11: =Inventory!$J$20*B11/365 -> 25.643836 | M11: =(Inventory!$J$21+Inventory!$J$22)*B11/365 -> 7.6931507 | N11: =SUM(D11:M11) -> 232.57798 | O11: =N11*MJ_PER_KWH -> 837.28073 | P11: =SUM(D11:G11) -> 133.17326 | Q11: =P11*MJ_PER_KWH/ROOM_AREA -> 31.961582 | R11: =N11/OCC -> 116.28899 | S11: =N11*EF_CLP -> 79.076513 | T11: =N11*EF_DEFAULT -> 162.80459
A12: Jul | B12: =Inputs!J11 -> 31 | C12: =IF(Inputs!K11=1,"Hot","Cool") -> Hot | D12: =AC_Baseline!E12 -> 99.573257 | E12: =Inventory!$J$10*B12/365 -> 7.44 | F12: =(Inventory!$J$8+Inventory!$J$9)*B12/365 -> 9.92 | G12: =(Inventory!$J$11+Inventory!$J$12)*B12/365 -> 17.36 | H12: =HotWater!G12 -> 36.373803 | I12: =(Inventory!$J$14+Inventory!$J$15)*B12/365 -> 12.555 | J12: =KAC_LABEL_KWH/LABEL_HOURS*B12*IF(Inputs!K11=1,KAC_H_HOT,KAC_H_COOL)*Inventory!$I$18 -> 8.8866667 | K12: =(Inventory!$J$16+Inventory!$J$17+Inventory!$J$19)*B12/365 -> 8.4883733 | L12: =Inventory!$J$20*B12/365 -> 26.49863 | M12: =(Inventory!$J$21+Inventory!$J$22)*B12/365 -> 7.949589 | N12: =SUM(D12:M12) -> 235.04532 | O12: =N12*MJ_PER_KWH -> 846.16315 | P12: =SUM(D12:G12) -> 134.29326 | Q12: =P12*MJ_PER_KWH/ROOM_AREA -> 32.230382 | R12: =N12/OCC -> 117.52266 | S12: =N12*EF_CLP -> 79.915409 | T12: =N12*EF_DEFAULT -> 164.53172
A13: Aug | B13: =Inputs!J12 -> 31 | C13: =IF(Inputs!K12=1,"Hot","Cool") -> Hot | D13: =AC_Baseline!E13 -> 99.573257 | E13: =Inventory!$J$10*B13/365 -> 7.44 | F13: =(Inventory!$J$8+Inventory!$J$9)*B13/365 -> 9.92 | G13: =(Inventory!$J$11+Inventory!$J$12)*B13/365 -> 17.36 | H13: =HotWater!G13 -> 37.029187 | I13: =(Inventory!$J$14+Inventory!$J$15)*B13/365 -> 12.555 | J13: =KAC_LABEL_KWH/LABEL_HOURS*B13*IF(Inputs!K12=1,KAC_H_HOT,KAC_H_COOL)*Inventory!$I$18 -> 8.8866667 | K13: =(Inventory!$J$16+Inventory!$J$17+Inventory!$J$19)*B13/365 -> 8.4883733 | L13: =Inventory!$J$20*B13/365 -> 26.49863 | M13: =(Inventory!$J$21+Inventory!$J$22)*B13/365 -> 7.949589 | N13: =SUM(D13:M13) -> 235.7007 | O13: =N13*MJ_PER_KWH -> 848.52253 | P13: =SUM(D13:G13) -> 134.29326 | Q13: =P13*MJ_PER_KWH/ROOM_AREA -> 32.230382 | R13: =N13/OCC -> 117.85035 | S13: =N13*EF_CLP -> 80.138239 | T13: =N13*EF_DEFAULT -> 164.99049
A14: Sep | B14: =Inputs!J13 -> 30 | C14: =IF(Inputs!K13=1,"Hot","Cool") -> Hot | D14: =AC_Baseline!E14 -> 99.573257 | E14: =Inventory!$J$10*B14/365 -> 7.2 | F14: =(Inventory!$J$8+Inventory!$J$9)*B14/365 -> 9.6 | G14: =(Inventory!$J$11+Inventory!$J$12)*B14/365 -> 16.8 | H14: =HotWater!G14 -> 38.371667 | I14: =(Inventory!$J$14+Inventory!$J$15)*B14/365 -> 12.15 | J14: =KAC_LABEL_KWH/LABEL_HOURS*B14*IF(Inputs!K13=1,KAC_H_HOT,KAC_H_COOL)*Inventory!$I$18 -> 8.6 | K14: =(Inventory!$J$16+Inventory!$J$17+Inventory!$J$19)*B14/365 -> 8.2145548 | L14: =Inventory!$J$20*B14/365 -> 25.643836 | M14: =(Inventory!$J$21+Inventory!$J$22)*B14/365 -> 7.6931507 | N14: =SUM(D14:M14) -> 233.84647 | O14: =N14*MJ_PER_KWH -> 841.84727 | P14: =SUM(D14:G14) -> 133.17326 | Q14: =P14*MJ_PER_KWH/ROOM_AREA -> 31.961582 | R14: =N14/OCC -> 116.92323 | S14: =N14*EF_CLP -> 79.507798 | T14: =N14*EF_DEFAULT -> 163.69253
A15: Oct | B15: =Inputs!J14 -> 31 | C15: =IF(Inputs!K14=1,"Hot","Cool") -> Hot | D15: =AC_Baseline!E15 -> 99.573257 | E15: =Inventory!$J$10*B15/365 -> 7.44 | F15: =(Inventory!$J$8+Inventory!$J$9)*B15/365 -> 9.92 | G15: =(Inventory!$J$11+Inventory!$J$12)*B15/365 -> 17.36 | H15: =HotWater!G15 -> 46.859944 | I15: =(Inventory!$J$14+Inventory!$J$15)*B15/365 -> 12.555 | J15: =KAC_LABEL_KWH/LABEL_HOURS*B15*IF(Inputs!K14=1,KAC_H_HOT,KAC_H_COOL)*Inventory!$I$18 -> 8.8866667 | K15: =(Inventory!$J$16+Inventory!$J$17+Inventory!$J$19)*B15/365 -> 8.4883733 | L15: =Inventory!$J$20*B15/365 -> 26.49863 | M15: =(Inventory!$J$21+Inventory!$J$22)*B15/365 -> 7.949589 | N15: =SUM(D15:M15) -> 245.53146 | O15: =N15*MJ_PER_KWH -> 883.91326 | P15: =SUM(D15:G15) -> 134.29326 | Q15: =P15*MJ_PER_KWH/ROOM_AREA -> 32.230382 | R15: =N15/OCC -> 122.76573 | S15: =N15*EF_CLP -> 83.480697 | T15: =N15*EF_DEFAULT -> 171.87202
A16: Nov | B16: =Inputs!J15 -> 30 | C16: =IF(Inputs!K15=1,"Hot","Cool") -> Cool | D16: =AC_Baseline!E16 -> 35.561878 | E16: =Inventory!$J$10*B16/365 -> 7.2 | F16: =(Inventory!$J$8+Inventory!$J$9)*B16/365 -> 9.6 | G16: =(Inventory!$J$11+Inventory!$J$12)*B16/365 -> 16.8 | H16: =HotWater!G16 -> 56.447576 | I16: =(Inventory!$J$14+Inventory!$J$15)*B16/365 -> 12.15 | J16: =KAC_LABEL_KWH/LABEL_HOURS*B16*IF(Inputs!K15=1,KAC_H_HOT,KAC_H_COOL)*Inventory!$I$18 -> 4.3 | K16: =(Inventory!$J$16+Inventory!$J$17+Inventory!$J$19)*B16/365 -> 8.2145548 | L16: =Inventory!$J$20*B16/365 -> 25.643836 | M16: =(Inventory!$J$21+Inventory!$J$22)*B16/365 -> 7.6931507 | N16: =SUM(D16:M16) -> 183.61099 | O16: =N16*MJ_PER_KWH -> 660.99958 | P16: =SUM(D16:G16) -> 69.161878 | Q16: =P16*MJ_PER_KWH/ROOM_AREA -> 16.598851 | R16: =N16/OCC -> 91.805497 | S16: =N16*EF_CLP -> 62.427738 | T16: =N16*EF_DEFAULT -> 128.5277
A17: Dec | B17: =Inputs!J16 -> 31 | C17: =IF(Inputs!K16=1,"Hot","Cool") -> Cool | D17: =AC_Baseline!E17 -> 35.561878 | E17: =Inventory!$J$10*B17/365 -> 7.44 | F17: =(Inventory!$J$8+Inventory!$J$9)*B17/365 -> 9.92 | G17: =(Inventory!$J$11+Inventory!$J$12)*B17/365 -> 17.36 | H17: =HotWater!G17 -> 71.436838 | I17: =(Inventory!$J$14+Inventory!$J$15)*B17/365 -> 12.555 | J17: =KAC_LABEL_KWH/LABEL_HOURS*B17*IF(Inputs!K16=1,KAC_H_HOT,KAC_H_COOL)*Inventory!$I$18 -> 4.4433333 | K17: =(Inventory!$J$16+Inventory!$J$17+Inventory!$J$19)*B17/365 -> 8.4883733 | L17: =Inventory!$J$20*B17/365 -> 26.49863 | M17: =(Inventory!$J$21+Inventory!$J$22)*B17/365 -> 7.949589 | N17: =SUM(D17:M17) -> 201.65364 | O17: =N17*MJ_PER_KWH -> 725.95311 | P17: =SUM(D17:G17) -> 70.281878 | Q17: =P17*MJ_PER_KWH/ROOM_AREA -> 16.867651 | R17: =N17/OCC -> 100.82682 | S17: =N17*EF_CLP -> 68.562238 | T17: =N17*EF_DEFAULT -> 141.15755
A18: Year | B18: =SUM(B6:B17) -> 365 | D18: =SUM(D6:D17) -> 810.81081 | E18: =SUM(E6:E17) -> 87.6 | F18: =SUM(F6:F17) -> 116.8 | G18: =SUM(G6:G17) -> 204.4 | H18: =SUM(H6:H17) -> 634.71811 | I18: =SUM(I6:I17) -> 147.825 | J18: =SUM(J6:J17) -> 78.69 | K18: =SUM(K6:K17) -> 99.94375 | ... P18: =SUM(P6:P17) -> 1219.6108 | Q18: =P18*MJ_PER_KWH/ROOM_AREA -> 292.70659 | R18: =SUM(R6:R17) -> 1293.1938 | S18: =SUM(S6:S17) -> 879.37181 | T18: =SUM(T6:T17) -> 1810.4714
A20: Check: monthly total - inventory total (must be 0) | N20: =ROUND(N18-HH_KWH,6) -> 0
A21: Check: room-only total - room inventory (must be 0) | P21: =ROUND(P18-ROOM_KWH,6) -> 0

Sheet Breakdown
A1: Energy breakdown, EUI and benchmarks
A2: EAC 2018 §8.1(g)(ii)-(iv): EUI, monthly EUI and percentage breakdown by installation.
A4: A. End-use breakdown - household (Room 1003B + allocated shared services)
A5: End-use | B5: kWh/yr | C5: % of total | D5: kWh/person/yr | E5: kg CO2e/yr (CLP) | F5: kg CO2e/yr (default 0.7)
A6: Air-conditioning | B6: =SUMIF(Inventory!$L$7:$L$22,A6,Inventory!$J$7:$J$22) -> 889.50081 | C6: =B6/$B$16 -> 0.34391627 | D6: =B6/OCC -> 444.75041 | E6: =B6*EF_CLP -> 302.43028 | F6: =B6*EF_DEFAULT -> 622.65057
A7: Hot water | B7: =SUMIF(Inventory!$L$7:$L$22,A7,Inventory!$J$7:$J$22) -> 634.71811 | C7: =B7/$B$16 -> 0.24540718 | D7: =B7/OCC -> 317.35905 | E7: =B7*EF_CLP -> 215.80416 | F7: =B7*EF_DEFAULT -> 444.30267
A8: Cooking | B8: =SUMIF(Inventory!$L$7:$L$22,A8,Inventory!$J$7:$J$22) -> 312 | C8: =B8/$B$16 -> 0.12063157 | D8: =B8/OCC -> 156 | E8: =B8*EF_CLP -> 106.08 | F8: =B8*EF_DEFAULT -> 218.4
A9: Plug loads | B9: =SUMIF(Inventory!$L$7:$L$22,A9,Inventory!$J$7:$J$22) -> 204.4 | C9: =B9/$B$16 -> 0.079029143 | D9: =B9/OCC -> 102.2 | E9: =B9*EF_CLP -> 69.496 | F9: =B9*EF_DEFAULT -> 143.08
A10: Lighting | B10: =SUMIF(Inventory!$L$7:$L$22,A10,Inventory!$J$7:$J$22) -> 166.075 | C10: =B10/$B$16 -> 0.064211178 | D10: =B10/OCC -> 83.0375 | E10: =B10*EF_CLP -> 56.4655 | F10: =B10*EF_DEFAULT -> 116.2525
A11: Ventilation | B11: =SUMIF(Inventory!$L$7:$L$22,A11,Inventory!$J$7:$J$22) -> 131.4 | C11: =B11/$B$16 -> 0.050804449 | D11: =B11/OCC -> 65.7 | E11: =B11*EF_CLP -> 44.676 | F11: =B11*EF_DEFAULT -> 91.98
A12: Air movement (fan) | B12: =SUMIF(Inventory!$L$7:$L$22,A12,Inventory!$J$7:$J$22) -> 87.6 | C12: =B12/$B$16 -> 0.033869633 | D12: =B12/OCC -> 43.8 | E12: =B12*EF_CLP -> 29.784 | F12: =B12*EF_DEFAULT -> 61.32
A13: Laundry | B13: =SUMIF(Inventory!$L$7:$L$22,A13,Inventory!$J$7:$J$22) -> 93.6 | C13: =B13/$B$16 -> 0.03618947 | D13: =B13/OCC -> 46.8 | E13: =B13*EF_CLP -> 31.824 | F13: =B13*EF_DEFAULT -> 65.52
A14: Drinking water | B14: =SUMIF(Inventory!$L$7:$L$22,A14,Inventory!$J$7:$J$22) -> 34.21875 | C14: =B14/$B$16 -> 0.013230325 | D14: =B14/OCC -> 17.109375 | E14: =B14*EF_CLP -> 11.634375 | F14: =B14*EF_DEFAULT -> 23.953125
A15: Refrigeration | B15: =SUMIF(Inventory!$L$7:$L$22,A15,Inventory!$J$7:$J$22) -> 32.875 | C15: =B15/$B$16 -> 0.012710778 | D15: =B15/OCC -> 16.4375 | E15: =B15*EF_CLP -> 11.1775 | F15: =B15*EF_DEFAULT -> 23.0125
A16: Total | B16: =SUM(B6:B15) -> 2586.3877 | C16: =SUM(C6:C15) -> 1 | D16: =SUM(D6:D15) -> 1293.1938 | E16: =SUM(E6:E15) -> 879.37181 | F16: =SUM(F6:F15) -> 1810.4714
A19: B. EAC 2018 §8.1(g)(iv) categories
A20: Category | B20: Room 1003B kWh/yr | C20: % (room) | D20: Household kWh/yr | E20: % (household) | F20: Room MJ/yr
A21: Air-conditioning | B21: =SUMIFS(Inventory!$J$7:$J$22,Inventory!$M$7:$M$22,A21,Inventory!$B$7:$B$22,"Room") -> 898.41081 | C21: =B21/$B$25 -> 0.7366373 | D21: =SUMIF(Inventory!$M$7:$M$22,A21,Inventory!$J$7:$J$22) -> 1108.5008 | E21: =D21/$D$25 -> 0.42859036 | F21: =B21*MJ_PER_KWH -> 3234.2789
A22: Lighting | B22: =SUMIFS(Inventory!$J$7:$J$22,Inventory!$M$7:$M$22,A22,Inventory!$B$7:$B$22,"Room") -> 116.8 | C22: =B22/$B$25 -> 0.095768256 | D22: =SUMIF(Inventory!$M$7:$M$22,A22,Inventory!$J$7:$J$22) -> 166.075 | E22: =D22/$D$25 -> 0.064211178 | F22: =B22*MJ_PER_KWH -> 420.48
A23: Others | B23: =SUMIFS(Inventory!$J$7:$J$22,Inventory!$M$7:$M$22,A23,Inventory!$B$7:$B$22,"Room") -> 204.4 | C23: =B23/$B$25 -> 0.16759445 | D23: =SUMIF(Inventory!$M$7:$M$22,A23,Inventory!$J$7:$J$22) -> 1311.8119 | E23: =D23/$D$25 -> 0.50719847 | F23: =B23*MJ_PER_KWH -> 735.84
A24: Lift & escalator | B24: 0 | C24: =B24/$B$25 -> 0 | D24: 0 | E24: =D24/$D$25 -> 0 | F24: =B24*MJ_PER_KWH -> 0
A25: Total | B25: =SUM(B21:B24) -> 1219.6108 | C25: =SUM(C21:C24) -> 1 | D25: =SUM(D21:D24) -> 2586.3877 | E25: =SUM(E21:E24) -> 1 | F25: =SUM(F21:F24) -> 4390.5989
A26: Lift & escalator: not applicable to the audited unit (hall lifts are outside the household boundary).
A28: C. Key performance indicators and Hong Kong benchmarks
A29: Indicator | B29: Value | C29: Unit | D29: Benchmark | E29: Benchmark basis | F29: Ratio to benchmark
A30: Room EUI (energy inside the 15 m² room) | B30: =ROOM_KWH/ROOM_AREA -> 81.307387 | C30: kWh/m²/yr | D30: =BM_HH_KWH*12/BM_HH_PERS/BM_FLOOR_PP -> 68.75 | E30: Typical HK home: 275 kWh/month ÷ 3 persons ÷ 16 m²/person (S7, S23) | F30: =IF(D30="","",B30/D30) -> 1.1826529
A31: Room EUI | B31: =ROOM_KWH*MJ_PER_KWH/ROOM_AREA -> 292.70659 | C31: MJ/m²/yr | D31: =D30*MJ_PER_KWH -> 247.5 | E31: As above, in MJ | F31: =IF(D31="","",B31/D31) -> 1.1826529
A32: Household electricity per person | B32: =HH_KWH/OCC -> 1293.1938 | C32: kWh/person/yr | D32: =BM_HH_KWH*12/BM_HH_PERS -> 1100 | E32: Typical HK household (S7) | F32: =IF(D32="","",B32/D32) -> 1.1756308
A33: Share of household energy used outside the room | B33: =SHARED_KWH/HH_KWH -> 0.52845011 | C33: % | E33: Shared washroom, kitchen, laundry | F33: =IF(D33="","",B33/D33)
A34: Room lighting power density | B34: =(CEIL_N*CEIL_W+DESK_N*DESK_W)/ROOM_AREA -> 4 | C34: W/m² | D34: =BEC_LPD -> 6.2 | E34: BEC 2021 max LPD, dormitory (S24) | F34: =IF(D34="","",B34/D34) -> 0.64516129
A35: Floor area per occupant | B35: =ROOM_AREA/OCC -> 7.5 | C35: m²/person | D35: =BM_FLOOR_PP -> 16 | E35: Median HK per-capita floor area (S23) | F35: =IF(D35="","",B35/D35) -> 0.46875
A36: Fresh water use per person | B36: =GHG_Inventory!B40 -> 70.571429 | C36: L/person/day | D36: =BM_WATER -> 120.9 | E36: HK domestic fresh water 2023/24 (S13) | F36: =IF(D36="","",B36/D36) -> 0.58371736
A37: AC share of room energy | B37: =Breakdown!B21/Breakdown!B25 -> 0.7366373 | C37: % | E37: Incl. desk fan | F37: =IF(D37="","",B37/D37)
A38: Hot water share of household energy | B38: =Breakdown!B7/Breakdown!B16 -> 0.24540718 | C38: % | F38: =IF(D38="","",B38/D38)

Sheet GHG_Inventory
A1: Greenhouse gas inventory - HK GHG Guidelines for Buildings (EPD/EMSD 2010) format
A2: Reporting entity: household of Room 1003B (2 occupants). Physical boundary: the room plus allocated shares of the shared washroom and kitchen, and the household's hall-laundry use. Baseline year: typical 12 months (data Jan-Oct 2026).
A4: SCOPE 1 - Direct emissions
A5: Table 1 - Stationary combustion
A6: Source | B6: Fuel | C6: Amount | D6: Unit | E6: CO2e factor | F6: kg CO2e/yr
A7: Cooking and water heating | B7: None - all-electric (induction hob, electric heater) | C7: 0 | D7: - | E7: 0 | F7: =C7*E7 -> 0
A9: Table 3 - HFC refrigerant (mass-balance method: inventory change)
A10: Equipment | B10: Refrigerant | C10: Cs (kg) | D10: Ci (kg) | E10: Cd (kg) | F10: Ce (kg) | G10: GWP | H10: kg CO2e/yr
A11: Room window AC | B11: R32 (HFC-32) | C11: 0 | D11: 0 | E11: 0 | F11: 0 | G11: =GWP_R32 -> 650 | H11: =(C11+D11-E11-F11)*G11 -> 0
A12: Kitchen split AC | B12: R-410A | C12: 0 | D12: 0 | E12: 0 | F12: 0 | G12: =GWP_R410A -> 1725 | H12: =(C12+D12-E12-F12)*G12 -> 0
A13: Occupants hold, buy and dispose of no refrigerant, so the Guideline mass-balance gives zero. A leak-rate screening estimate is added below so fugitive HFCs are not omitted.
A15: Screening estimate - IPCC 2006 operating leak rate (included in Scope 1)
A16: Equipment | B16: Refrigerant | C16: Charge (kg) | D16: Leak rate /yr | E16: GWP | F16: Household share | G16: kg CO2e/yr
A17: Room window AC | B17: R32 | C17: =AC_CHARGE -> 0.4 | D17: =LEAK -> 0.04 | E17: =GWP_R32 -> 650 | F17: 1 | G17: =C17*D17*E17*F17 -> 10.4
A18: Kitchen split AC | B18: R-410A | C18: =KAC_CHARGE -> 1.4 | D18: =LEAK -> 0.04 | E18: =GWP_R410A -> 1725 | F18: =OCC/KIT_USERS -> 0.0625 | G18: =C18*D18*E18*F18 -> 6.0375
A19: Scope 1 total | G19: =F7+H11+H12+G17+G18 -> 16.4375
A21: SCOPE 2 - Energy indirect emissions (Table 5: purchased electricity, CLP Power)
A22: Facility / source | B22: Electricity (kWh/yr) | C22: CLP-specific factor (kg/kWh) | D22: Territory default (kg/kWh) | E22: kg CO2e/yr (CLP) | F22: kg CO2e/yr (default)
A23: Room 1003B (incl. Octopus-metered AC) | B23: =Inventory!D27 -> 1219.6108 | C23: =EF_CLP -> 0.34 | D23: =EF_DEFAULT -> 0.7 | E23: =B23*C23 -> 414.66768 | F23: =B23*D23 -> 853.72757
A24: Shared washroom (own showers + 2/4 of fan & lights) | B24: =Inventory!D28 -> 782.54311 | C24: =EF_CLP -> 0.34 | D24: =EF_DEFAULT -> 0.7 | E24: =B24*C24 -> 266.06466 | F24: =B24*D24 -> 547.78017
A25: Shared kitchen (own cooking + 2/32 of fixed loads) | B25: =Inventory!D29 -> 490.63375 | C25: =EF_CLP -> 0.34 | D25: =EF_DEFAULT -> 0.7 | E25: =B25*C25 -> 166.81547 | F25: =B25*D25 -> 343.44362
A26: Hall laundry (own use) | B26: =Inventory!D30 -> 93.6 | C26: =EF_CLP -> 0.34 | D26: =EF_DEFAULT -> 0.7 | E26: =B26*C26 -> 31.824 | F26: =B26*D26 -> 65.52
A27: Scope 2 total | B27: =SUM(B23:B26) -> 2586.3877 | E27: =SUM(E23:E26) -> 879.37181 | F27: =SUM(F23:F26) -> 1810.4714
A28: Table 6 - Towngas: not applicable (no Towngas or LPG used).
A30: SCOPE 3 - Other indirect emissions (optional under the Guidelines)
A31: Quantity | B31: Value | C31: Unit | D31: Basis
A32: Shower water | B32: =SHOWER_LPD -> 45 | C32: L/person/day | D32: HotWater sheet
A33: Drinking water (dispenser) | B33: =DRINK_L -> 2 | C33: L/person/day | D33: Reported
A34: Basin, cooking and dish-washing | B34: =OTHER_L -> 15 | C34: L/person/day | D34: Assumed
A35: Laundry water | B35: =WASH_L*LAUNDRY_WK/7 -> 8.5714286 | C35: L/person/day | D35: 60 L per weekly load
A36: Paper purchased (Pi) | B36: =SHEETS_SEM*SEMS*SHEET_G/1000*OCC -> 2 | C36: kg/yr (household) | D36: 100 sheets/semester each
A37: Paper recycled (Pr) | B37: =B36*RECYCLE -> 1 | C37: kg/yr | D37: Half recycled (assumed)
A38: Paper in storage at start / end (Ps, Pe) | B38: 0 | C38: kg | D38: Negligible
A40: Fresh water per person | B40: =SUM(B32:B35) -> 70.571429 | C40: L/person/day
A41: Household fresh water | B41: =B40*365*OCC/1000 -> 51.517143 | C41: m3/yr
A42: Household seawater (toilet flushing) | B42: =FLUSH_L*365*OCC/1000 -> 21.9 | C42: m3/yr | D42: 5 flushes x 6 L/person/day
A44: Guideline item | B44: Quantity | C44: Unit | D44: Emission factor | E44: Factor unit | F44: kg CO2e/yr | G44: Factor basis
A45: Table 7 - Paper waste to landfill | B45: =B38+B36-B37-B38 -> 1 | C45: kg | D45: =PAPER_EF -> 4.8 | E45: kg CO2e/kg | F45: =B45*D45 -> 4.8 | G45: Guideline default 4.8
A46: Table 8 - Fresh water (WSD) | B46: =B41 -> 51.517143 | C46: m3 | D46: =WSD_FRESH*EF_DEFAULT -> 0.4368 | E46: kg CO2e/m3 | F46: =B46*D46 -> 22.502688 | G46: 0.624 kWh/m3 × 0.7
A47: Table 9 - Sewage (DSD) | B47: =B41*SEWER_FRAC -> 51.517143 | C47: m3 | D47: =DSD_KWH*EF_DEFAULT -> 0.203 | E47: kg CO2e/m3 | F47: =B47*D47 -> 10.45798 | G47: 0.29 kWh/m3 × 0.7
...

Sheet Lifestyle_Scope3
A1: Daily-activity extension - the auditor's personal Scope 3 footprint
A2: Reported separately from the building inventory (GHG Protocol / ISO 14064-1 Scope 3 categories). Per auditor only, not per household.
A5: Activity | B5: Quantity | C5: Unit | D5: Emission factor | E5: Factor unit | F5: kg CO2e/yr | G5: Basis
A6: MTR commute (18 km x 2 x 6 days/week) | B6: =COMMUTE_KM_WK*WEEKS -> 10368 | C6: p-km | D6: =MTR_EF -> 0.0723 | E6: kg CO2e/p-km | F6: =B6*D6 -> 749.6064 | G6: MTR CDP 2022 (S17); 48 weeks
A7: Other MTR trips (22 km x 2 x 3/month) | B7: =HOME_KM_MONTH*MONTHS_IN_HK -> 1452 | C7: p-km | D7: =MTR_EF -> 0.0723 | E7: kg CO2e/p-km | F7: =B7*D7 -> 104.9796 | G7: 11 months in HK
A8: Flights (4 legs, table below) | B8: =D18 -> 14334.516 | C8: p-km | D8: =F8/B8 -> 0.11803205 | E8: kg CO2e/p-km | F8: =F18 -> 1691.9323 | G8: DESNZ 2025 economy incl. RF (S18)
A9: Diet - mixed (medium meat-eater) | B9: 365 | C9: days | D9: =DIET_EF -> 5.63 | E9: kg CO2e/day | F9: =B9*D9 -> 2054.95 | G9: Scarborough et al. 2014 (S19)
A10: Lifestyle total | F10: =SUM(F6:F9) -> 4601.4683
A13: Flight leg | B13: Great-circle km | C13: Haul | D13: Distance incl. 8% uplift (km) | E13: Factor (kg CO2e/p-km) | F13: kg CO2e
A14: Hong Kong (HKG) - Delhi (DEL) | B14: 3747 | C14: Long-haul | D14: =B14*FL_UPLIFT -> 4046.76 | E14: =IF(C14="Long-haul",EF_LONG,EF_SHORT) -> 0.11704 | F14: =D14*E14 -> 473.63279
A15: Delhi (DEL) - Hong Kong (HKG) | B15: 3747 | C15: Long-haul | D15: =B15*FL_UPLIFT -> 4046.76 | E15: =IF(C15="Long-haul",EF_LONG,EF_SHORT) -> 0.11704 | F15: =D15*E15 -> 473.63279
A16: Delhi (DEL) - Goa (GOI) | B16: 1503.1 | C16: Short-haul | D16: =B16*FL_UPLIFT -> 1623.348 | E16: =IF(C16="Long-haul",EF_LONG,EF_SHORT) -> 0.1258 | F16: =D16*E16 -> 204.21718
A17: Goa (GOI) - Hong Kong (HKG) | B17: 4275.6 | C17: Long-haul | D17: =B17*FL_UPLIFT -> 4617.648 | E17: =IF(C17="Long-haul",EF_LONG,EF_SHORT) -> 0.11704 | F17: =D17*E17 -> 540.44952
A18: Flights total | B18: =SUM(B14:B17) -> 13272.7 | D18: =SUM(D14:D17) -> 14334.516 | F18: =SUM(F14:F17) -> 1691.9323
A21: Personal footprint (auditor) | B21: kg CO2e/yr | C21: % of personal total
A22: Home energy & water (household inventory ÷ 2) | B22: =TOT_CLP/OCC -> 469.55972 | C22: =B22/$B$26 -> 0.092596554
A23: MTR travel | B23: =F6+F7 -> 854.586 | C23: =B23/$B$26 -> 0.16852323
A24: Flights | B24: =F8 -> 1691.9323 | C24: =B24/$B$26 -> 0.3336468
A25: Diet | B25: =F9 -> 2054.95 | C25: =B25/$B$26 -> 0.40523342
A26: Personal total | B26: =SUM(B22:B25) -> 5071.028 | C26: =SUM(C22:C25) -> 1
A27: HK per-capita emissions 2023 (territorial, S10) | B27: =BM_HK_T*1000 -> 4580
A28: Ratio: personal total / HK per-capita (different scope - see report) | B28: =B26/B27 -> 1.1072114

Sheet EMO_Register
A1: Energy Management Opportunities (EAC 2018 §6.2 categories; EE-EAes Part 3 types)
A2: Cat I = housekeeping, no cost; Cat II = low-cost operational changes; Cat III = higher capital cost. Types: LG lighting, AC air-conditioning, EL electrical, LE lift/escalator, Others. Capital costs are indicative and must be confirmed by quotation.
A5: Ref | B5: Cat. | C5: Type | D5: Responsible party | E5: Energy management opportunity | F5: Basis of saving estimate | G5: Facility saving (kWh/yr) | H5: Household share (kWh/yr) | I5: Household saving (HK$/yr) | J5: Indicative capital cost (HK$) | K5: Simple payback (yr) | L5: Service life (yr) | M5: Facility saving (kg CO2e/yr) | N5: Household saving (kg CO2e/yr) | O5: Recommendation
A6: EMO-01 | B6: I | C6: AC | D6: Occupants | E6: Raise the AC set-point from 25 °C to 26 °C and keep the 20 W desk fan running for air movement | F6: 3% of AC energy per +1 °C (S14) | G6: =AC_KWH*DEG_SAVING*(26-AC_SETPOINT) -> 24.324324 | H6: =G6 -> 24.324324 | I6: =H6*TARIFF -> 34.2 | J6: 0 | K6: =IF(J6=0,0,IFERROR(J6/(G6*TARIFF),"n/a")) -> 0 | L6: - | M6: =G6*EF_CLP -> 8.2702703 | N6: =H6*EF_CLP -> 8.2702703 | O6: Implement now
A7: EMO-02 | B7: I | C7: AC | D7: Occupants | E7: Use the AC's built-in timer to switch off 2 h before waking in hot months (12 to 10 h/day) | F7: 2/12 of hot-season AC energy | G7: =AC_KWH_HOT*2/AC_H_HOT -> 99.573257 | H7: =G7 -> 99.573257 | I7: =H7*TARIFF -> 140 | J7: 0 | K7: =IF(J7=0,0,IFERROR(J7/(G7*TARIFF),"n/a")) -> 0 | L7: - | M7: =G7*EF_CLP -> 33.854908 | N7: =H7*EF_CLP -> 33.854908 | O7: Implement now
A8: EMO-03 | B8: I | C8: AC | D8: Occupants | E8: Clean the AC filter fortnightly in summer, wipe the soiled louvres, close the curtain against late-afternoon NW sun | F8: 5% of AC energy (S26, S32) | G8: =AC_KWH*0.05 -> 40.540541 | H8: =G8 -> 40.540541 | I8: =H8*TARIFF -> 57 | J8: 0 | K8: =IF(J8=0,0,IFERROR(J8/(G8*TARIFF),"n/a")) -> 0 | L8: - | M8: =G8*EF_CLP -> 13.783784 | N8: =H8*EF_CLP -> 13.783784 | O8: Implement now
A9: EMO-04 | B9: I | C9: LG | D9: Occupants | E9: Use the desk task lights instead of both ceiling battens for 3 of the 6 lit hours | F9: 2 x 20 W x 3 h/day avoided | G9: =CEIL_N*CEIL_W*3*365/1000 -> 43.8 | H9: =G9 -> 43.8 | I9: =H9*TARIFF -> 61.5828 | J9: 0 | K9: =IF(J9=0,0,IFERROR(J9/(G9*TARIFF),"n/a")) -> 0 | L9: - | M9: =G9*EF_CLP -> 14.892 | N9: =H9*EF_CLP -> 14.892 | O9: Implement now
A10: EMO-05 | B10: I | C10: Others | D10: Occupants | E10: Shorten showers from 5 to 4 minutes | F10: 20% of shower heating energy | G10: =HW_KWH*(1-4/SHOWER_MIN) -> 126.94362 | H10: =G10 -> 126.94362 | I10: =H10*TARIFF -> 178.48273 | J10: 0 | K10: =IF(J10=0,0,IFERROR(J10/(G10*TARIFF),"n/a")) -> 0 | L10: - | M10: =G10*EF_CLP -> 43.160831 | N10: =H10*EF_CLP -> 43.160831 | O10: Implement now
A11: EMO-06 | B11: I | C11: Others | D11: Occupants | E11: Lower the delivered shower temperature from 40 °C to 38 °C (turn the heater dial down) | F11: 2 K of the annual-average temperature rise | G11: =HW_KWH*2/HW_AVG_DT -> 77.166162 | H11: =G11 -> 77.166162 | I11: =H11*TARIFF -> 108.49562 | J11: 0 | K11: =IF(J11=0,0,IFERROR(J11/(G11*TARIFF),"n/a")) -> 0 | L11: - | M11: =G11*EF_CLP -> 26.236495 | N11: =H11*EF_CLP -> 26.236495 | O11: Implement now
A12: EMO-07 | B12: I | C12: EL | D12: Occupants | E12: Laptop power management: lower brightness, sleep after 10 min idle, battery-saver mode | F12: 15% of laptop energy (assumed) | G12: =Inventory!J11*0.15 -> 28.47 | H12: =G12 -> 28.47 | I12: =H12*TARIFF -> 40.02882 | J12: 0 | K12: =IF(J12=0,0,IFERROR(J12/(G12*TARIFF),"n/a")) -> 0 | L12: - | M12: =G12*EF_CLP -> 9.6798 | N12: =H12*EF_CLP -> 9.6798 | O12: Implement now
A13: EMO-08 | B13: I | C13: Others | D13: Occupants | E13: Cook with lids, match pan to the induction zone, batch-cook two meals per session | F13: 20% of cooking energy (assumed) | G13: =Inventory!J20*0.2 -> 62.4 | H13: =G13 -> 62.4 | I13: =H13*TARIFF -> 87.7344 | J13: 0 | K13: =IF(J13=0,0,IFERROR(J13/(G13*TARIFF),"n/a")) -> 0 | L13: - | M13: =G13*EF_CLP -> 21.216 | N13: =H13*EF_CLP -> 21.216 | O13: Implement now
A14: EMO-09 | B14: II | C14: AC | D14: Hall (Student Residence Office) | E14: Washroom exhaust fan: replace 24 h running with an occupancy / humidistat run-on control (~8 h/day) | F14: 16 of 24 fan-hours avoided | G14: =WR_FAN_W*(WR_FAN_H-8)*365/1000 -> 175.2 | H14: =G14*OCC/WR_USERS -> 87.6 | I14: =H14*TARIFF -> 123.1656 | J14: 800 | K14: =IF(J14=0,0,IFERROR(J14/(G14*TARIFF),"n/a")) -> 3.2476601 | L14: 10 | M14: =G14*EF_CLP -> 59.568 | N14: =H14*EF_CLP -> 29.784 | O14: Recommend to hall
A15: EMO-10 | B15: II | C15: AC | D15: Hall (Student Residence Office) | E15: Kitchen AC: 7-day timer + occupancy interlock, set-point locked at 25.5 °C (8 to 5 h/day hot, 4 to 2 h/day cool) | F15: Label 0.573 kW x hours avoided | G15: =KAC_LABEL_KWH/LABEL_HOURS*((KAC_H_HOT-5)*DAYS_HOT+(KAC_H_COOL-2)*DAYS_COOL) -> 524.02667 | H15: =G15*OCC/KIT_USERS -> 32.751667 | I15: =H15*TARIFF -> 46.048843 | J15: 1000 | K15: =IF(J15=0,0,IFERROR(J15/(G15*TARIFF),"n/a")) -> 1.3572545 | L15: 10 | M15: =G15*EF_CLP -> 178.16907 | N15: =H15*EF_CLP -> 11.135567 | O15: Recommend to hall
A16: EMO-11 | B16: II | C16: Others | D16: Hall (Student Residence Office) | E16: Water dispenser: enable night set-back / timer on hot and ice tanks (00:00-06:00) | F16: 25% of dispenser energy (assumed) | G16: =DISP_KWH_DAY*365*0.25 -> 136.875 | H16: =G16*OCC/KIT_USERS -> 8.5546875 | I16: =H16*TARIFF -> 12.027891 | J16: 200 | K16: =IF(J16=0,0,IFERROR(J16/(G16*TARIFF),"n/a")) -> 1.0392512 | L16: 10 | M16: =G16*EF_CLP -> 46.5375 | N16: =H16*EF_CLP -> 2.9085938 | O16: Recommend to hall
A17: EMO-12 | B17: II | C17: Others | D17: Hall (Student Residence Office) | E17: Fit a WELS Grade-1 low-flow showerhead (9 to 7 L/min) in the shared washroom | F17: 22% of shower energy and water, 4 users | G17: =HW_KWH/OCC*WR_USERS*(1-7/SHOWER_FLOW) -> 282.09694 | H17: =HW_KWH*(1-7/SHOWER_FLOW) -> 141.04847 | I17: =H17*TARIFF -> 198.31415 | J17: 250 | K17: =IF(J17=0,0,IFERROR(J17/(G17*TARIFF),"n/a")) -> 0.63031308 | L17: 5 | M17: =G17*EF_CLP -> 95.912958 | N17: =H17*EF_CLP -> 47.956479 | O17: Recommend to hall
A18: EMO-13 | B18: II | C18: AC | D18: Hall (Student Residence Office) | E18: Annual professional clean of the window-AC coil and louvres (heavy soiling seen in photo 03b) | F18: 3% of AC energy (S26) | G18: =AC_KWH*0.03 -> 24.324324 | H18: =G18 -> 24.324324 | I18: =H18*TARIFF -> 34.2 | J18: 400 | K18: =IF(J18=0,0,IFERROR(J18/(G18*TARIFF),"n/a")) -> 11.695906 | L18: 1 | M18: =G18*EF_CLP -> 8.2702703 | N18: =H18*EF_CLP -> 8.2702703 | O18: Recommend on hygiene grounds; bundle with routine maintenance (EAC 7.6.4)
